<?xml version="1.0"?>
<robot xmlns:xacro="http://www.ros.org/wiki/xacro" >

    <xacro:include filename="inertial_macros.xacro"/>

    <material name="white">
        <color rgba="1 1 1 1" />
    </material>

    <material name="orange">
        <color rgba="1 0.3 0.1 1"/>
    </material>

    <material name="blue">
        <color rgba="0.2 0.2 1 1"/>
    </material>

    <material name="black">
        <color rgba="0 0 0 1"/>
    </material>

    <!-- BASE LINK -->

    <link name="base_link">

    </link>


    <!-- CHASSIS LINK -->

    <joint name="chassis_joint" type="fixed">
        <parent link="base_link"/>
        <child link="chassis"/>
        <origin xyz="-0.15 0 0"/>
    </joint>

    <link name="chassis">
        <visual>
            <origin xyz="0.15 0 0.075"/>
            <geometry>
                <box size="0.3 0.2 0.15"/>
            </geometry>
            <material name="white"/>
        </visual>
        <collision>
            <origin xyz="0.15 0 0.075"/>
            <geometry>
                <box size="0.3 0.2 0.15"/>
            </geometry>
        </collision>
        <xacro:inertial_box mass="1" x="0.3" y="0.2" z="0.15">
            <origin xyz="0.15 0 0.075" rpy="0 0 0"/>
        </xacro:inertial_box>
    </link>

    <gazebo reference="chassis">
        <material>
            Gazebo/White
        </material>
    </gazebo>
    <!-- LEFT WHEEL LINK -->
    <joint name="left_wheel_joint" type="continuous">
        <parent link="base_link"/>
        <child link="l_frontwheel"/>
        <origin xyz="0.0 0.1 0.0" rpy="-${pi/2} 0.0 0.0"/>
        <axis xyz="0.0 0.0 1.0"/>
    </joint>

    <link name="l_frontwheel">
        <visual>
            <geometry>
                <cylinder radius="0.10" length="0.05"/>
            </geometry>
            <material name="blue"/>
        </visual>
        <collision>
            <geometry>
                <cylinder radius="0.10" length="0.05"/>
            </geometry>
        </collision>
        <xacro:inertial_cylinder mass="0.1" length="0.5" radius="0.1">
            <origin xyz="0 0 0" rpy="0 0 0"/>
        </xacro:inertial_cylinder>
    </link>

    <gazebo reference="l_frontwheel">
        <material>
            Gazebo/Blue
        </material>
    </gazebo>
    <!-- RIGHT WHEEL LINK -->
    <joint name="right_wheel_joint" type="continuous">
        <parent link="base_link"/>
        <child link="r_frontwheel"/>
        <origin xyz="0.0 -0.1 0.0" rpy="${pi/2} 0.0 0.0"/>
        <axis xyz="0.0 0.0 -1.0"/>
    </joint>

    <link name="r_frontwheel">
        <visual>
            <geometry>
                <cylinder radius="0.10" length="0.05"/>
            </geometry>
            <material name="blue"/>
        </visual>
        <collision>
            <geometry>
                <cylinder radius="0.10" length="0.05"/>
            </geometry>
        </collision>
        <xacro:inertial_cylinder mass="0.1" length="0.05" radius="0.1">
            <origin xyz="0 0 0" rpy="0 0 0"/>
        </xacro:inertial_cylinder>
    </link>

    <gazebo reference="r_frontwheel">
        <material>
            Gazebo/Blue
        </material>
    </gazebo>
    <!-- PIPE LINK -->
    <joint name="pipe_joint" type="fixed">
        <parent link="base_link"/>
        <child link="pipe"/>
        <origin xyz="-0.15 0.0 0.075"/>
    </joint>

    <link name="pipe">
        <visual>
            <origin rpy="0.0 ${pi/2} 0.0"/>
            <geometry>
                <cylinder radius="0.02" length="0.05"/>
            </geometry>
            <material name="orange"/>
        </visual>
        <collision>
            <origin rpy="0.0 ${pi/2} 0.0"/>
            <geometry>
                <cylinder radius="0.02" length="0.05"/>
            </geometry>
        </collision>
        <xacro:inertial_cylinder mass="0.1" length="0.05" radius="0.02">
            <origin xyz="0 0 0" rpy="0 0 0"/>
        </xacro:inertial_cylinder>
    </link>

    <gazebo reference="pipe">
        <material>
            Gazebo/Orange
        </material>
    </gazebo>
    <!-- BACKWARD BASELINK -->
    <joint name="backward_base_joint" type="fixed">
        <parent link="pipe"/>
        <child link="backward_base"/>
        <origin xyz="-0.175 0.0 -0.075"/>
    </joint>

    <link name="backward_base">
        
    </link>

    <!-- BACKWARD CHASSIS LINK-->
    <joint name="backward_chassis_joint" type="fixed">
        <parent link="backward_base"/>
        <child link="backward_chassis"/>
        <origin xyz="-0.15 0 0"/>
    </joint>
    <link name="backward_chassis">
        <visual>
            <origin xyz="0.15 0 0.075"/>
            <geometry>
                <box size="0.3 0.2 0.15"/>
            </geometry>
            <material name="white"/>
        </visual>
        <collision>
            <origin xyz="0.15 0 0.075"/>
            <geometry>
                <box size="0.3 0.2 0.15"/>
            </geometry>
        </collision>
        <xacro:inertial_box mass="1" x="0.3" y="0.2" z="0.15">
            <origin xyz="0.15 0 0.075" rpy="0 0 0"/>
        </xacro:inertial_box>
    </link>

    <gazebo reference="backward_chassis">
        <material>
            Gazebo/White
        </material>
    </gazebo>
    <!-- BACKWARD LEFT WHEEL LINK -->
    <joint name="backward_left_wheel_joint" type="continuous">
        <parent link="backward_base"/>
        <child link="l_backwheel"/>
        <origin xyz="0.0 0.1 0.0" rpy="-${pi/2} 0.0 0.0"/>
        <axis xyz="0.0 0.0 1.0"/>
    </joint>

    <link name="l_backwheel">
        <visual>
            <geometry>
                <cylinder radius="0.1" length="0.05"/>
            </geometry>
            <material name="blue"/>
        </visual>
        <collision>
            <geometry>
                <cylinder radius="0.1" length="0.05"/>
            </geometry>
        </collision>
        <xacro:inertial_cylinder mass="0.1" length="0.5" radius="0.1">
            <origin xyz="0 0 0" rpy="0 0 0"/>
        </xacro:inertial_cylinder>
    </link>

    <gazebo reference="l_backwheel">
        <material>
            Gazebo/Blue
        </material>
        <mu1 value="0.0000001"/>
        <mu2 value="0.0000001"/>
    </gazebo>
    <!--BACKWARD RIGHT WHEEL LINK -->
    <joint name="backward_right_wheel_joint" type="continuous">
        <parent link="backward_base"/>
        <child link="r_backwheel"/>
        <origin xyz="0.0 -0.1 0.0" rpy="${pi/2} 0.0 0.0"/>
        <axis xyz="0.0 0.0 -1.0"/>
    </joint>

    <link name="r_backwheel">
        <visual>
            <geometry>
                <cylinder radius="0.1" length="0.05"/>
            </geometry>
            <material name="blue"/>
        </visual>
        <collision>
            <geometry>
                <cylinder radius="0.1" length="0.05"/>
            </geometry>
        </collision>
        <xacro:inertial_cylinder mass="0.1" length="0.05" radius="0.1">
            <origin xyz="0 0 0" rpy="0 0 0"/>
        </xacro:inertial_cylinder>
    </link>
    <gazebo reference="r_backwheel">
        <material>
            Gazebo/Blue
        </material>
        <mu1 value="0.0000001"/>
        <mu2 value="0.0000001"/>
    </gazebo>
</robot>